Workbook

Sheet 自动卡用户手册
A1: 这张自动卡是基于赛博朋克红的规则书和群里已有的自动卡设计的，感谢前人的贡献！
A2: 主要是想让卡好看点，视觉上更符合赛博朋克红的感觉，同时更适配面团 | I2: （就我感觉规则书上的卡看着眼睛疼吗？）
A3: 面团建议是可以只打印人物卡，别的边跑边看手机
A5: 根据规则书中的车卡顺序你会依次写RP卡，人物卡，装备卡，状态表
A7: 里面有些自动数值设计不符合规则书，我知道
A8: 例如人性值上限，技能使用的是加点而非等级
A9: 一般情况下不影响游戏，如果你觉得有问题就自己改改
A11: 里面有些数值看着不对劲，这是因为我在里面塞了一点例子，填完自己会好的
A13: 会自动计算属性、技能基准、生命值上限、人性值上限和一些杂七杂八的东西
A15: 你装备的武器和护甲请填写在装备卡中，会自动出现在人物卡
A16: 使用的赛博义体填在状态表里，扣除的人性值会自动减少人性值上限
A17: 如果你通过任何手段降低了义体减少的人性值，直接在状态表的义体统计里修改
A19: 所有使用 | B19: 这个背景颜色 | D19: 的单元格均为自动计算
A20: 随便改会弄坏自动表 | C20: （基本上手动填的就是白色底色）
A22: 有重大问题群里@zcrss，就是我，不保证能改
A24: 推荐使用MiSans Semibold字体以获得最佳体验
A26: 最后，您可以删除此工作表
A27: 祝您游戏愉快！

Sheet 人物卡
B2: 基础信息 | I2: 人物属性 | N2: 调整属性/结果 | S2: 技能
J4: 智力 | K4: 8 | P4: =K4+O4 -> 8 | T4: 感官技能 | V4: 调整 | W4: 加点 | X4: 技能基准 | Z4: 教育技能 | AB4: 调整 | AC4: 加点 | AE4: 技能基准 | AG4: 战斗技能 | AI4: 调整 | AJ4: 加点 | AK4: 技能基准
T5: 专注 | W5: 4 | X5: =V5+W5+$P$14 -> 10 | Z5: 会计 | AE5: =AC5+AB5+$P$4 -> 8 | AG5: 搏击 | AK5: =AI5+AJ5+$P$8 -> 6
J6: 反应 | K6: 6 | P6: =K6+O6-Y32 -> 6 | T6: 隐藏/发现物品 | W6: 2 | X6: =V6+W6+$P$4 -> 10 | Z6: 驯兽 | AE6: =AC6+AB6+$P$4 -> 8 | AG6: 闪避 | AJ6: 2 | AK6: =AI6+AJ6+$P$8 -> 8
T7: 唇语 | X7: =V7+W7+$P$4 -> 8 | Z7: 官场 | AE7: =AC7+AB7+$P$4 -> 8 | AG7: [x2] | AH7: （武术流派） | AK7: =AI7+ROUNDDOWN(AJ7/2,0)+$P$8 -> 6
J8: 敏捷 | K8: 6 | P8: =K8+O8-Y32 -> 6 | T8: 察觉 | W8: 4 | X8: =V8+W8+$P$4 -> 12 | Z8: 商务 | AE8: =AC8+AB8+$P$4 -> 8 | AG8: 近战武器 | AK8: =AI8+AJ8+$P$8 -> 6
T9: 追踪 | X9: =V9+W9+$P$4 -> 8 | Z9: 写作 | AE9: =AC9+AB9+$P$4 -> 8 | AG9: 远程武器技能 | AI9: 调整 | AJ9: 加点 | AK9: 技能基准
J10: 技术 | K10: 8 | P10: =K10+O10 -> 8 | T10: 身体技能 | V10: 调整 | W10: 加点 | X10: 技能基准 | Z10: 犯罪学 | AE10: =AC10+AB10+$P$4 -> 8 | AG10: 弓道 | AK10: =AI10+AJ10+$P$6 -> 6
T11: 运动 | X11: =V11+W11+$P$8 -> 6 | Z11: 密码学 | AE11: =AC11+AB11+$P$4 -> 8 | AG11: [x2]自动武器 | AK11: =AI11+ROUNDDOWN(AJ11/2,0)+$P$6 -> 6
J12: 酷 | K12: 6 | P12: =K12+O12 -> 6 | T12: 柔韧 | X12: =V12+W12+$P$8 -> 6 | Z12: 推理 | AC12: 4 | AE12: =AC12+AB12+$P$4 -> 12 | AG12: 手枪 | AJ12: 3 | AK12: =AI12+AJ12+$P$6 -> 9
T13: 舞蹈 | X13: =V13+W13+$P$8 -> 6 | Z13: 通识 | AC13: 2 | AE13: =AC13+AB13+$P$4 -> 10 | AG13: [x2]重武器 | AK13: =AI13+ROUNDDOWN(AJ13/2,0)+$P$6 -> 6
J14: 意志 | K14: 6 | P14: =K14+O14 -> 6 | T14: 忍耐 | X14: =V14+W14+$P$14 -> 6 | Z14: 赌博 | AE14: =AC14+AB14+$P$4 -> 8 | AG14: 长管武器 | AK14: =AI14+AJ14+$P$6 -> 6
C15: 头像 | T15: 抗折磨/耐药 | W15: 4 | X15: =V15+W15+$P$14 -> 10 | Z15: 图书馆检索 | AC15: 2 | AE15: =AC15+AB15+$P$4 -> 10 | AG15: 社交技能 | AI15: 调整 | AJ15: 加点 | AK15: 技能基准
C16: 玩家 | D16: 懒骨头 | J16: 运气 | K16: 5 | P16: =K16+O16 -> 5 | T16: 潜行 | W16: 2 | X16: =V16+W16+$P$8 -> 8 | Z16: 科学 | AC16: 3 | AE16: =AC16+AB16+$P$4 -> 11 | AG16: 贿赂 | AK16: =AI16+AJ16+$P$12 -> 6
C17: 姓名 | D17: “祸害” | T17: 操作技能 | V17: 调整 | W17: 加点 | X17: 技能基准 | Z17: 战术 | AE17: =AC17+AB17+$P$4 -> 8 | AG17: 交谈 | AK17: =AI17+AJ17+$P$22 -> 5
C18: 外号 | D18: “祸害” | J18: 移速 | K18: 4 | P18: =K18+O18-Y32 -> 4 | T18: 陆地载具 | W18: 2 | X18: =V18+W18+$P$6 -> 8 | Z18: 野外生存 | AE18: =AC18+AB18+$P$4 -> 8 | AG18: 察言观色 | AJ18: 7 | AK18: =AI18+AJ18+$P$22 -> 12
C19: 年龄 | D19: 31 | E19: 性别 | F19: 男 | T19: [x2]空中载具 | X19: =V19+ROUNDDOWN(W19/2,0)+$P$6 -> 6 | Z19: 语言 | AE19: =AC19+AB19+$P$4 -> 8 | AG19: 审讯 | AK19: =AI19+AJ19+$P$12 -> 6
C20: 故乡 | J20: 体格 | K20: 5 | P20: =K20+O20 -> 5 | T20: 水上载具 | X20: =V20+W20+$P$6 -> 6 | Z20: ┣→ | AA20: 街头俚语 | AC20: 2 | AE20: =AC20+AB20+$P$4 -> 10 | AG20: 说服 | AK20: =AI20+AJ20+$P$12 -> 6
C21: 等级 | D21: 4 | E21: 声望 | T21: 骑术 | X21: =V21+W21+$P$6 -> 6 | Z21: ┣→ | AA21: 英语 | AB21: 4 | AE21: =AC21+AB21+$P$4 -> 12 | AG21: 个人装扮 | AK21: =AI21+AJ21+$P$12 -> 6
C22: 原生家庭 | D22: 被收养的孤儿 | J22: 共情 | K22: 8 | P22: =K22+O22+O23 -> 5 | T22: 表演技能 | V22: 调整 | W22: 加点 | X22: 技能基准 | Z22: ┗→ | AE22: =AC22+AB22+$P$4 -> 8 | AG22: 街头智慧 | AJ22: 4 | AK22: =AI22+AJ22+$P$12 -> 10
O23: =INT(MOD(K32,100)/10)-K22 -> -3 | T23: 表演 | X23: =V23+W23+$P$12 -> 6 | Z23: 本地专家 | AE23: =AC23+AB23+$P$4 -> 8 | AG23: 交易 | AJ23: 2 | AK23: =AI23+AJ23+$P$12 -> 8
J24: 可用点数 | K24: 62 | O24: 先攻 调整 | T24: 乐器使用 | X24: =V24+W24+$P$10 -> 8 | Z24: ┣→ | AA24: 奥德卡多营地周边 | AE24: =AC24+AB24+$P$4 -> 8 | AG24: 服饰与风格 | AK24: =AI24+AJ24+$P$12 -> 6
B25: 职业 | J25: 剩余点数 | K25: =K24-SUM(K4:K22) -> 0 | T25: ┣→ | X25: =V25+W25+$P$10 -> 8 | Z25: ┣→ | AE25: =AC25+AB25+$P$4 -> 8 | AG25: 技术技能 | AI25: 调整 | AJ25: 加点 | AK25: 技能基准
T26: ┗→ | X26: =V26+W26+$P$10 -> 8 | Z26: ┗→ | AE26: =AC26+AB26+$P$4 -> 8 | AG26: 空中载具技术 | AK26: =AI26+AJ26+$P$10 -> 8
C27: 职业名 | D27: 技医 | E27: 等级 | F27: 3 | AG27: 基础技术 | AJ27: 4 | AK27: =AI27+AJ27+$P$10 -> 12
E28: 能力 | F28: 外科 | I28: 状态 | AG28: 赛博技术 | AJ28: 5 | AK28: =AI28+AJ28+$P$10 -> 13
C29: 兼职1 | D29: 技工 | E29: 等级 | F29: 1 | J29: 影响血量的意志与体格直接加在人物属性 | S29: 护甲与武器 | AG29: [x2]爆破学 | AK29: =AI29+ROUNDDOWN(AJ29/2,0)+$P$10 -> 8
E30: 能力 | F30: 应急专精 | J30: 生命值 | N30: / | O30: =IF(ISBLANK(K20),0,10+ROUNDUP((K20+K14)/2,0)*5) -> 40 | AG30: [x2]电子/安全技术 | AJ30: 4 | AK30: =AI30+ROUNDDOWN(AJ30/2,0)+$P$10 -> 10
C31: 兼职2 | E31: 等级 | T31: 护甲 | W31: 剩余/SP | Y31: 罚值 | AG31: 急救 | AJ31: 10 | AK31: =AI31+AJ31+$P$10 -> 18
E32: 能力 | J32: 人性值 | K32: =IF(ISBLANK(K22),0,MIN(10*K22-状态表!I5,O32)) -> 55 | N32: / | O32: =MAX(10*K22-状态表!J5,0) -> 74 | T32: 头 | U32: =装备卡!D39 -> “手术外套” | X32: =装备卡!J39 -> 11 | Y32: =MAX(装备卡!K39:K41) -> 0 | AA32: 此处罚值不需要再填调整属性，会自动计算 | AG32: [x2]强化急救 | AJ32: 14 | AK32: =AI32+ROUNDDOWN(AJ32/2,0)+$P$10 -> 15
T33: 身 | U33: =装备卡!D40 -> 0 | X33: =装备卡!J40 -> 0 | AG33: 伪造 | AK33: =AI33+AJ33+$P$10 -> 8
C34: 备注 | J34: 人性值变化导致的共情变化会被自动计算 | T34: 盾 | U34: =装备卡!D41 -> 0 | X34: =装备卡!J41 -> 0 | AG34: 地面载具技术 | AK34: =AI34+AJ34+$P$10 -> 8
J35: 严重伤势 | O35: 效果 | T35: 武器 | V35: 伤害 | W35: 剩余/弹药 | Y35: 攻速 | AA35: 备注 | AG35: 绘画/雕刻/摄影 | AK35: =AI35+AJ35+$P$10 -> 8
T36: =装备卡!C5 -> “止疼药” | V36: =装备卡!G5 -> 3D6 | X36: =装备卡!H5 -> 8 | Y36: =装备卡!I5 -> 2 | AG36: 摄影/摄像 | AK36: =AI36+AJ36+$P$10 -> 8
AG37: 开锁 | AK37: =AI37+AJ37+$P$10 -> 8
T38: =装备卡!C11 -> “麻醉针” | V38: =装备卡!G11 -> 2d6 | X38: =装备卡!H11 -> 0 | Y38: =装备卡!I11 -> 0 | AG38: 扒窃 | AK38: =AI38+AJ38+$P$10 -> 8
AG39: 海洋载具技术 | AK39: =AI39+AJ39+$P$10 -> 8
T40: =装备卡!C17 -> “吐真剂” | V40: =装备卡!G17 -> 1d6 | X40: =装备卡!H17 -> 0 | Y40: =装备卡!I17 -> 2 | AG40: 武器技术 | AK40: =AI40+AJ40+$P$10 -> 8
T42: =装备卡!C23 -> 0 | V42: =装备卡!G23 -> 0 | X42: =装备卡!H23 -> 0 | Y42: =装备卡!I23 -> 0 | AG42: 可用点数 | AI42: 86 | AJ42: 剩余 | AK42: =AI42-SUM(W5:W9)-SUM(W11:W16)-SUM(W18:W21)-SUM(W23:W26)-SUM(AC5:AC26)-SUM(AJ5:AJ8)-SUM(AJ10:AJ14)-SUM(AJ16:AJ24)-SUM(AJ26:AJ40) -> 0
AG43: 加点列浅红色标记的为必须点的基础加点，技能列红色[x2]的在加点列+2才会+1技能基准
...

Sheet 装备卡
B2: 武器 | E2: 下方已有武器为示例，使用前请删除 | P2: 钱包 | W2: 背包 | Y2: 下方已有物品为示例，使用前请删除
C4: 武器名称 | E4: 武器类型 | F4: 武器技能 | G4: 单次伤害 | H4: 弹药容量 | I4: 攻速 | J4: 需要手数 | K4: 能否隐藏 | L4: 成本 | M4: 价值 | Q4: 专项预算 | R4: 时尚预算 | X4: 物品 | Y4: 描述 | Z4: 数量 | AA4: 成本 | AB4: 价值
C5: “止疼药” | E5: 重型手枪 | G5: 3D6 | H5: 8 | I5: 2 | J5: 1 | K5: 能 | L5: 100 | R5: 义体赞助 | X5: 掌上代理 | AA5: 100
C6: 备注 | D6: 一把旧式重型手枪，枪身磨损严重，握把缠着医用胶布。祸害很少主动使用它，但如果病人、帮派成员或赛博疯子试图在祸害堂里闹事，他会很自然地把它从医生外套里摸出来。 -----“别动。这个止疼快，就是副作用有点大。” | Q6: 流动资金 | R6: 初始资金 | S6: 3200
C7: 配件 | R7: 收益 | S7: =SUM(成长表!M5:M50) -> 0 | X7: 手电筒 | AA7: 20
R8: 购物支出 | S8: =SUM(L5,L7:L9,L11,L13:L15,L17,L19:L21,L23,L25:L27,L29,L31:L33,L39:L41)+状态表!H5+SUM(AA5:AA42) -> 2890
R9: 消耗支出 | X9: 手铐 | AA9: 50
C10: 武器名称 | E10: 武器类型 | F10: 武器技能 | G10: 单次伤害 | H10: 弹药容量 | I10: 攻速 | J10: 需要手数 | K10: 能否隐藏 | L10: 成本 | M10: 价值 | R10: 总计 | S10: =SUM(S6:T7)-SUM(S8:T9) -> 310
C11: “麻醉针” | E11: 电击棍 | G11: 2d6 | J11: 1 | K11: 不能 | L11: 100 | Q11: 会自动计算表格里填的，已消耗的消耗品和购买服务等花费填在消耗支出里 | X11: 气动注射器 | AA11: 50
C12: 备注 | D12: 一根伪装成旧拐杖的电击棍，平时靠在诊疗台旁边。祸害声称这是“非侵入式安抚设备”，但被它打过的人通常不这么认为。 -----“只要被轻轻扎一下，你看，这不就老实了？”
C13: 配件 | X13: 技医工具包 | AA13: 100
P14: 衣食住行 | S14: 这里不会参与自动计算
X15: 技工工具包 | AA15: 500
C16: 武器名称 | E16: 武器类型 | F16: 武器技能 | G16: 单次伤害 | H16: 弹药容量 | I16: 攻速 | J16: 需要手数 | K16: 能否隐藏 | L16: 成本 | M16: 价值 | Q16: 生活风格 | S16: 花费
C17: “吐真剂” | E17: 小刀 | G17: 1d6 | I17: 2 | K17: 能 | L17: 50 | Q17: 普通人造食品级别 | S17: 300 | X17: 个人卫生包 | AA17: 20
C18: 备注 | D18: 一把经过改造的高硬度手术刀，刀身极薄，刀柄上缠着发黄的医用胶布。祸害坚持说这不是武器，而是一件“沟通工具”。 ----- “我只是想和你敞开心扉聊聊” | Q18: 住所 | S18: 花费
C19: 配件 | Q19: 自己的诊所 | S19: 0 | X19: 基础弹药 | Z19: 30 | AA19: 300
Q20: 本月已支付 | S20: 总开销
S21: =S19+S17 -> 300
C22: 武器名称 | E22: 武器类型 | F22: 武器技能 | G22: 单次伤害 | H22: 弹药容量 | I22: 攻速 | J22: 需要手数 | K22: 能否隐藏 | L22: 成本 | M22: 价值 | Q22: 时尚衣物 | S22: 数量 | T22: 单价
Q23: 通用朋克（鞋类） | S23: 2 | T23: 20
C24: 备注 | Q24: 通用朋克（上装） | S24: 3 | T24: 50
C25: 配件 | Q25: 通用朋克（下装） | S25: 5 | T25: 20
C28: 武器名称 | E28: 武器类型 | F28: 武器技能 | G28: 单次伤害 | H28: 弹药容量 | I28: 攻速 | J28: 需要手数 | K28: 能否隐藏 | L28: 成本 | M28: 价值
C30: 备注
C31: 配件
R33: 时尚总费用 | T33: =S23*T23+S24*T24+S25*T25+S26*T26+S27*T27+S28*T28+S29*T29+S30*T30+S31*T31+S32*T32 -> 290
B36: 护甲 | E36: 下方已有护甲为示例，使用前请删除
C38: 护甲部位 | D38: 护甲名称 | E38: 护甲类型 | G38: 备注 | J38: 阻滞力 | K38: 护甲惩罚 | L38: 成本 | M38: 价值
C39: 头部 | D39: “手术外套” | E39: 轻型装甲夹克 | G39: 可穿在旧医生外套下，轻便、柔软，不影响手术动作 | J39: 11 | K39: 0 | L39: 100
C40: 身体
C41: 盾牌

Sheet 状态表
B2: 义体统计 | E2: 下方已有义体为示例，使用前请删除 | M2: 伤势 | P2: 仅供参考，不参与自动计算 | AA2: 精神状态 | AD2: 仅供参考，不参与自动计算
H4: 总花费 | I4: 总人性损失 | J4: 总人性上限损失 | N4: 生命值 | O4: 总生命值 | P4: 伤势状态 | Q4: 伤势效果 | T4: 救治难度 | U4: 左侧伤势状态自动计算， 生命值变化时请调整人物卡 | AB4: 人性值 | AC4: 人性值上限 | AD4: 共情 | AE4: 精神状态
H5: =SUM(H7:H55) -> 1400 | I5: =SUM(I7:I55) -> 25 | J5: =SUM(J7:J55) -> 6 | N5: =人物卡!K30 -> 0 | O5: =人物卡!O30 -> 40 | P5: =IF(N5=0,"致命伤",IF(N5<O5,IF(N5<O5/2,"重伤","轻伤"),"健康")) -> 致命伤 | Q5: =IF($P$5="健康","无",IF($P$5="轻伤","无",IF($P$5="重伤","所有动作检定-2",IF($P$5="致命伤","所有动作的检定 -4，移速属性 -6（最低剩余 1）",2)))) -> 所有动作的检定 -4，移速属性 -6（最低剩余 1） | T5: {=IF($P$5="健康","无",IF($P$5="轻伤","10",IF($P$5="重伤","13",IF($P$5="致命伤","15",_xleta.XIRR))))} -> 15 | AB5: =人物卡!K32 -> 55 | AC5: =人物卡!O32 -> 74 | AD5: =人物卡!P22 -> 5 | AE5: =IF(AD5<0,"严重赛博精神病",IF(AD5=0,"赛博精神病",IF(AD5=1,"分离性精神障碍",IF(AD5=2,"边缘分离性精神障碍","健康")))) -> 健康
C6: 基础义体 | D6: 插槽 | E6: 组件名 | F6: 安装设施 | G6: 描述和数据 | H6: 花费 | I6: 安装人性损失 | J6: 人性上限损失 | AB6: 人性值变动记录
C7: 生物监测器 | F7: 购物中心 | G7: “为了防止自己猝死装的” | H7: 100 | I7: 0 | J7: 0 | N7: 身体严重伤势 | AB7: 类型 | AD7: 人性值变化
C8: 神经链路 | F8: 诊所 | G8: 安装了“交互接口” | H8: 1000 | I8: 14 | J8: 4 | N8: 是否受伤 | O8: 2D6 | P8: 严重伤势 | Q8: 伤势效果 | V8: 紧急处理 | W8: 治愈
C9: 赛博义眼 | F9: 诊所 | G9: 单眼，安装了“字幕功能”和“微显微镜” | H9: 300 | I9: 11 | J9: 2 | N9: 否 | O9: 2 | P9: 断臂 | Q9: 断掉的那只手臂，没了。那只手里拿着的任何东西都掉了。基础死亡豁免惩罚减值 +1。 | V9: 做不到 | W9: 手术DV17
N11: 否 | O11: 3 | P11: 断手 | Q11: 断掉的那只手，没了。那只手里拿着的任何东西都掉了。基础死亡豁免惩罚减值 +1。 | V11: 做不到 | W11: 手术DV17
N13: 否 | O13: 4 | P13: 气胸 | Q13: 移速属性 -2（最低 1）， 基础死亡豁免惩罚减值 +1。 | V13: 强化急救DV15 | W13: 手术DV15
N15: 否 | O15: 5 | P15: 肋骨骨折 | Q15: 在每个你徒步行进了超过 4m 的回合后，你都要重新受到这个严重伤势的额外伤害，直接从生命值里扣除。 | V15: 强化急救DV13 | W15: 强化急救DV15/ 手术DV13
N17: 否 | O17: 6 | P17: 手臂骨折 | Q17: 骨折的手臂无法再用来干别的事了，那只手里拿着的任何东西，都掉了。 | V17: 强化急救DV13 | W17: 强化急救DV15/ 手术DV13
N19: 否 | O19: 7 | P19: 体内异物 | Q19: 在每个你徒步行进了超过 4m 的回合后，你都要重新受到这个严重伤势的额外伤害，直接从生命值里扣除。 | V19: 急救/强化急救DV13 | W19: 紧急处理可治愈 | AA19: 药物状态
N21: 否 | O21: 8 | P21: 小腿/大腿骨折 | Q21: 移速属性 -4（最低 1） | V21: 强化急救DV13 | W21: 强化急救DV15/ 手术DV13 | AB21: 是否成瘾 | AC21: 药物名称 | AD21: 备注
N23: 否 | O23: 9 | P23: 肌肉撕裂 | Q23: 近战攻击判定 -2 | V23: 急救/强化急救DV13 | W23: 紧急处理可治愈
N25: 否 | O25: 10 | P25: 脊柱受伤 | Q25: 在你的下个回合里你无法使用其他动作，但仍然可以进行移动动作。基础死亡豁免惩罚减值 +1。 | V25: 强化急救DV15 | W25: 手术DV15
N27: 否 | O27: 11 | P27: 手指粉碎性骨折 | Q27: 用到那只手的任何动作判定 -4 | V27: 强化急救DV13 | W27: 手术DV15
N29: 否 | O29: 12 | P29: 断腿 | Q29: 断掉的那条腿，没了。移速 -6（最低 1）。你无法闪避攻击。基础死亡豁免惩罚减值 +1。 | V29: 做不到 | W29: 手术DV17
N31: 头部严重伤势
N32: 是否受伤 | O32: 2D6 | P32: 严重伤势 | Q32: 伤势效果 | V32: 紧急处理 | W32: 治愈
N33: 否 | O33: 2 | P33: 失去眼睛 | Q33: 你的一只眼睛不见了。远程攻击和所有需要视觉的觉察判定 -4。基础死亡豁免惩罚减值 +1。 | V33: 做不到 | W33: 手术DV17
N35: 否 | O35: 3 | P35: 脑损伤 | Q35: 所有动作判定 -2，基础死亡豁免惩罚减值 +1。 | V35: 做不到 | W35: 手术DV17
C37: 人性变动事件 | E37: 描述 | G37: 效果 | H37: 花费 | I37: 人性损失变化 | N37: 否 | O37: 4 | P37: 眼睛受损 | Q37: 远程攻击和所有需要视觉的觉察判定 -2。 | V37: 强化急救DV15 | W37: 手术DV13
C38: 示例 | E38: 示例 | G38: 人性损失事件 | H38: 示例 | I38: 7
C39: 示例 | E39: 示例 | G39: 心理治疗 | H39: 示例 | I39: -7 | N39: 否 | O39: 5 | P39: 脑震荡 | Q39: 所有动作判定 -2。 | V39: 急救/强化急救DV13 | W39: 紧急处理可治愈
N41: 否 | O41: 6 | P41: 领骨骨折 | Q41: 需要说话的所有动作判定 -4。 | V41: 强化急救DV15 | W41: 强化急救DV15/ 手术DV13
N43: 否 | O43: 7 | P43: 头部异物 | Q43: 在每个你徒步行进了超过 4m 的回合后，你都要重新 受到这个严重伤势的额外伤害，直接从生命值里扣除。 | V43: 急救/强化急救DV13 | W43: 紧急处理可治愈
N45: 否 | O45: 8 | P45: 挥鞭伤 | Q45: 基础死亡豁免惩罚减值 +1。 | V45: 强化急救DV13 | W45: 强化急救/ 手术DV13
N47: 否 | O47: 9 | P47: 颅骨骨裂 | Q47: 瞄准你头部的瞄准射击造成的伤害在减去阻滞力之后倍数变为 3( 而不是 2)，基础死亡豁免惩罚减值 +1。 | V47: 强化急救DV15 | W47: 强化急救/ 手术DV15
N49: 否 | O49: 10 | P49: 耳朵受损 | Q49: 在每个你徒步行进了超过 4m 的回合后，下个回合将无法做出移动动作。所有需要听力的觉察判定 -2。 | V49: 强化急救DV13 | W49: 手术DV13
N51: 否 | O51: 11 | P51: 气管破裂 | Q51: 你说话只有含混的嘶嘶气声，无法说话。基础死亡豁免惩罚减值 +1。 | V51: 做不到 | W51: 手术DV15
N53: 否 | O53: 12 | P53: 失去耳朵 | Q53: 你的一只耳朵不见了。在每个你徒步行进了超过 4m的回合后，下个回合将无法做出移动动作。所有需要听力的觉察判定 -4，基础死亡豁免惩罚减值 +1。 | V53: 做不到 | W53: 手术DV17

Sheet RP卡
B2: 生命路径 | G2: 朋友 | S2: 精神病症状
C4: 风格 | H4: 名字 | I4: 你们的关系 | L4: 详细描述
C5: 文化区域 | D5: 夜城街区 | H5: “算盘” | I5: 黑市药贩 | L5: 长期给祸害堂供药，嘴上互相嫌弃，但偶尔会给便宜货。两人合作久，算是暗中支持祸害运作的人。
C6: 母语 | D6: 中文 | H6: “老铁” | I6: 常客 / 欠账病人 | L6: 公司战争退下来的佣兵，常年接低价危险委托，身上旧伤和廉价义体问题不断。每次快死或修不起义体时都会跑到祸害堂，欠了不少医药费。祸害嘴上骂他但通常还是会救。
C7: 性格 | D7: 孤僻、嘴毒、刻薄、警惕、怪异。病人不听话会被骂，但据说只要还能喘气，他通常都会救。 | H7: “螺母” | I7: 拆机匠 / 零件供应 | L7: 提供二手义体零件和修补材料，“祸害”觉得他的东西十件有三件能用，螺母觉得这已经是最高评价。
C8: 发型 | D8: 凌乱黑发，夹杂少量灰白发丝
C9: 衣着风格 | D9: 旧医生外套混合中式长衫，口袋里塞满奇怪的医疗工具、针包、义体接口线和药剂
C10: 动机
C11: 个性 | D11: 怪异、古怪的怪医，治疗手段独特而高超，手法野，往往把手术、草药、义体修复、电刺激混在一起
C12: 最看重 | D12: 诊所、医疗工具、病人的生死
C13: 最在乎 | D13: 病人是否配合、规矩是否被遵守
C14: 观点 | D14: 有钱看病，没钱滚蛋
C15: 宝物 | D15: “吐真剂”、“医嘱”、旧针包、医疗箱 | G15: 爱情
C16: 目标 | D16: 别让诊所倒闭，少死几个“不遵医嘱的傻逼”
C17: 家庭背景 | H17: 名字 | I17: 发生了什么 | L17: 详细描述
C18: 原生家庭 | D18: 不明，街坊邻居都叫他姓陆医生，是个可怜孩子，再多的就不肯说了 | I18: “我一没钱二没权三没时间，谁看得上我？再问手术费加倍” ---来自“祸害”某次的手术期间
C19: 童年环境 | D19: 街头、黑诊所、旧药柜、手术台、欠账本之间成长
C20: 家庭危机 | D20: 不谈过去，任何打听过去的人都会被怼或翻倍收费
C26: 基于职业的生命路径
C27: “祸害”是一名旧城区赤脚医生，经营黑诊所“祸害堂”。他医术高超但手段怪异，主要救治帮派成员、街头佣兵和正规医疗体系不愿接收的人。他依靠黑市药品、二手义体零件和街头人情维持诊所运转，名声很差但救活过很多人。
G28: 人物背景故事
H30: 雨下得很脏。 两个人站在巷子口躲雨，一个捂着还在流血的手臂，另一个往巷子深处看。 “你确定是这儿？” “牌子都在那儿了，还能错？” 巷子尽头挂着一块旧招牌，被红油漆和荧光涂料刷得乱七八糟。牌子像是原本写过什么正经话，但已经被涂得只剩几道模糊旧痕。现在最显眼的，是一行歪斜刺眼的大字： 有病来治，爱死不死。 受伤的那人沉默了一下。 “这地方看着不像诊所。” “本来就不像。”同伴说，“祸害堂嘛。你见过哪家诊所门口挂着半截香炉、两个监控、三串不知道干什么的电线，还有一只会骂人的电子鹦鹉？” “电子鹦鹉？” 话音刚落，门口那只缺了半边羽毛的机械鸟忽然亮起红眼。 “穷鬼别进！穷鬼别进！先答题，后看病！” 受伤的人嘴角抽了一下。 “这医生什么毛病？” “怪毛病多着呢。”同伴压低声音，“听说他给人看病的时候，一边放老戏曲，一边开手术灯；药柜上不写药名，写‘吃了别死’、‘疼了活该’、‘三号蠢货专用’；手术台旁边还摆着财神、除颤器和一台拆了一半的自动售货机。” “自动售货机干什么用？” “不知道。有人说是麻醉机，有人说是呼吸机，还有人说它真能卖饮料。” 受伤的人看着自己流血的胳膊，脸色有点发白。 “他到底会不会治？” “会。”同伴说，“虽然看着像骗子，但医术是真的高。枪伤、感染、义体排异、神经烧坏，他都敢接。正规医院不收的，帮派医生不敢动的，很多最后都往这儿送。” “怎么治？” “这就更怪了。”同伴咧了咧嘴，“别人做手术用无菌器械，他用无菌器械、旧针包、草药贴、电刺激线，还有一把看起来像修摩托的扳手。上次有人义体接口烧了，他一边骂人一边拿电线重新接，接完还给人贴了张膏药，说‘祖传散热方案’。” “这听起来像谋杀。” “但人活了。” “……那还行。” 同伴又看了一眼那扇门。 “而且他人也怪。明明才三十出头，看着像四十多，整天一副刚从停尸房加班出来的样子。说话特别难听，病人疼得叫，他骂人家吵；病人不叫，他又骂人家快死了还装硬汉。” 受伤的人皱眉。 “那心肠怎么样？” “传闻说不坏。”同伴耸肩，“有人说他嘴上骂‘爱死不死’，但真送到手术台上，通常还是会救。也有人说他给没钱的小孩赊过药，不过这话别当他面说。” “为什么？” “他会加钱。” 雨水顺着招牌往下滴，红色油漆被冲得像血一样。 受伤的人深吸一口气，刚要往前走，诊所门忽然“咔哒”一声开了。 冷白色灯光从门缝里切出来。 一个穿旧医生外套的男人站在门后，眼下青黑，嘴里叼着烟，手上还戴着一只沾着消毒水味的手套。他扫了一眼那条流血的手臂，又看向两人。 “谁要治？” 受伤的人举手。 男人冷笑了一声。 “看出来了，血都替你报名了。” 他往外走了半步。 “进门先答题。” 受伤的人愣住。 “现在？” 男人皱起眉。 “不然等你死了我问尸体？” 他低头点了点烟灰，声音懒得要命。 “听好，什么东西，越治越欠揍？”
B40: 敌人
C42: 名字 | D42: 关系如何 | E42: 什么导致的 | J42: 他会怎么样来找你 | M42: 你打算怎么做 | P42: 详细描述
C43: 陈主任 | D43: 由于其各种手段使“祸害”非常讨厌他 | E43: 不想“祸害”的才华被埋没，用强硬手段逼迫诊所关门，逼迫其为自己手下的公司医疗部人员工作 | J43: 通过检查、举报、行政施压，或者派人来“劝”祸害堂停业整顿 | M43: 来一次骂一次，让他赶紧滚。或是想办法搞到正规的营业执照让他永远闭嘴 | P43: 陈主任是公司医疗体系的人，表面温和专业，实际只关心成本、责任和公司利益。他不一定想杀“祸害”，但很想让祸害堂闭嘴、关门，或者至少别再破坏公司医疗的生意。但是偶尔会偷偷的资助“祸害堂”
C44: “金牙” | D44: 互相看不顺眼 | E44: 金牙卖翻新义体、劣质神经接口和来路不明的医疗零件，祸害修过太多他害出来的病人，还当众骂过他的货是“装进身体里的垃圾” | J44: 派小弟来威胁，断祸害的零件来源，或者把医疗事故甩锅给“祸害” | M44: 继续拆他的台，但不主动追杀；遇到他的烂货就修，修完顺手告诉病人是谁害的 | P44: 金牙是黑市义体商，笑起来满口金属牙，最擅长把废品包装成高级货。他和“祸害”不是血仇，但利益冲突很深。祸害看不起他的货，金牙也讨厌“祸害”坏他好事。
C45: 红姐 | D45: 她恨透了“祸害”，“祸害”却对其心怀愧疚 | E45: 她的老公曾被送进祸害堂抢救，但伤势太重没能活下来。红姐认定祸害没有尽全力，或者至少隐瞒了什么 | J45: 在街头散布传闻，找人上门质问，或者在祸害接委托时突然出现阻挠 | M45: 由于心怀愧疚，不解释太多，保持距离；如果她真的遇到危险，“祸害”大概率还是会救 | P45: 红姐不是坏人，她只是失去了亲人，需要一个能恨的人。“祸害”不喜欢解释失败，也不愿意把手术细节拿来证明自己无辜，所以这段关系一直僵着。

Sheet 成长表
B2: I.P.统计 | E2: 此工作表不参与自动计算，为记录用。 | I2: 成长记录 | L2: 此工作表不参与自动计算，为记录用。
C4: I.P.点 | J4: 时间 | K4: 模组 | L4: 获得声望 | M4: 获得资金 | N4: 获得物品 | O4: 人性事件 | P4: 人性增减 | Q4: 资金来源 | R4: 物品来源 | S4: 重要的时刻
C5: 已获得 | D5: 属性消耗 | E5: 技能消耗 | F5: 剩余
D6: =SUM(F9:F18) -> 0 | E6: =SUM(F21:F50) -> 0 | F6: =C6-D6-E6 -> 0
C7: 能力成长表
C8: 职业能力 | D8: 初始等级 | E8: 成长等级 | F8: 已消耗I.P.
C9: 魅力冲击
C10: 战斗直觉
C11: 交互界面
C12: 能工巧匠
C13: 医疗圣手
C14: 公众信誉
C15: 团队合作
C16: 后备支援
C17: 八面玲珑
C18: 引擎之友
C19: 技能成长表
C20: 技能名称 | D20: 原始技能 | E20: 成长技能 | F20: 已消耗I.P.
